[2025-01-16T04:59:12.522+0000] {local_task_job_runner.py:120} INFO - ::group::Pre task execution logs
[2025-01-16T04:59:12.556+0000] {taskinstance.py:2076} INFO - Dependencies all met for dep_context=non-requeueable deps ti=<TaskInstance: ETL.extract_data manual__2025-01-16T04:59:10.678545+00:00 [queued]>
[2025-01-16T04:59:12.564+0000] {taskinstance.py:2076} INFO - Dependencies all met for dep_context=requeueable deps ti=<TaskInstance: ETL.extract_data manual__2025-01-16T04:59:10.678545+00:00 [queued]>
[2025-01-16T04:59:12.565+0000] {taskinstance.py:2306} INFO - Starting attempt 1 of 1
[2025-01-16T04:59:12.578+0000] {taskinstance.py:2330} INFO - Executing <Task(PythonOperator): extract_data> on 2025-01-16 04:59:10.678545+00:00
[2025-01-16T04:59:12.583+0000] {standard_task_runner.py:63} INFO - Started process 5161 to run task
[2025-01-16T04:59:12.587+0000] {standard_task_runner.py:90} INFO - Running: ['airflow', 'tasks', 'run', 'ETL', 'extract_data', 'manual__2025-01-16T04:59:10.678545+00:00', '--job-id', '8', '--raw', '--subdir', 'DAGS_FOLDER/ETL.py', '--cfg-path', '/tmp/tmpp0ncvhd3']
[2025-01-16T04:59:12.589+0000] {standard_task_runner.py:91} INFO - Job 8: Subtask extract_data
[2025-01-16T04:59:12.638+0000] {task_command.py:426} INFO - Running <TaskInstance: ETL.extract_data manual__2025-01-16T04:59:10.678545+00:00 [running]> on host airflow-scheduler
[2025-01-16T04:59:12.714+0000] {taskinstance.py:2648} INFO - Exporting env vars: AIRFLOW_CTX_DAG_OWNER='Ajied(WhatsApp), Ajied(Email)' AIRFLOW_CTX_DAG_ID='ETL' AIRFLOW_CTX_TASK_ID='extract_data' AIRFLOW_CTX_EXECUTION_DATE='2025-01-16T04:59:10.678545+00:00' AIRFLOW_CTX_TRY_NUMBER='1' AIRFLOW_CTX_DAG_RUN_ID='manual__2025-01-16T04:59:10.678545+00:00'
[2025-01-16T04:59:12.715+0000] {taskinstance.py:430} INFO - ::endgroup::
[2025-01-16T04:59:12.716+0000] {logging_mixin.py:188} INFO - Extracting data from PostgreSQL...
[2025-01-16T04:59:12.717+0000] {taskinstance.py:441} INFO - ::group::Post task execution logs
[2025-01-16T04:59:12.717+0000] {taskinstance.py:2905} ERROR - Task failed with exception
Traceback (most recent call last):
  File "/home/airflow/.local/lib/python3.10/site-packages/airflow/models/taskinstance.py", line 465, in _execute_task
    result = _execute_callable(context=context, **execute_callable_kwargs)
  File "/home/airflow/.local/lib/python3.10/site-packages/airflow/models/taskinstance.py", line 432, in _execute_callable
    return execute_callable(context=context, **execute_callable_kwargs)
  File "/home/airflow/.local/lib/python3.10/site-packages/airflow/models/baseoperator.py", line 401, in wrapper
    return func(self, *args, **kwargs)
  File "/home/airflow/.local/lib/python3.10/site-packages/airflow/operators/python.py", line 235, in execute
    return_value = self.execute_callable()
  File "/home/airflow/.local/lib/python3.10/site-packages/airflow/operators/python.py", line 252, in execute_callable
    return self.python_callable(*self.op_args, **self.op_kwargs)
  File "/opt/airflow/dags/ETL.py", line 10, in extract
    return extract_data()
  File "/opt/airflow/dags/resources/extract.py", line 51, in extract_data
    products_df = pl.read_database_uri(query=products, uri=connection_url)
AttributeError: module 'polars' has no attribute 'read_database_uri'
[2025-01-16T04:59:12.731+0000] {taskinstance.py:1206} INFO - Marking task as FAILED. dag_id=ETL, task_id=extract_data, run_id=manual__2025-01-16T04:59:10.678545+00:00, execution_date=20250116T045910, start_date=20250116T045912, end_date=20250116T045912
[2025-01-16T04:59:12.740+0000] {standard_task_runner.py:110} ERROR - Failed to execute job 8 for task extract_data (module 'polars' has no attribute 'read_database_uri'; 5161)
[2025-01-16T04:59:12.760+0000] {local_task_job_runner.py:240} INFO - Task exited with return code 1
[2025-01-16T04:59:12.777+0000] {taskinstance.py:3503} INFO - 0 downstream tasks scheduled from follow-on schedule check
[2025-01-16T04:59:12.782+0000] {local_task_job_runner.py:222} INFO - ::endgroup::
