[2025-01-16T04:40:56.201+0000] {local_task_job_runner.py:120} INFO - ::group::Pre task execution logs
[2025-01-16T04:40:56.250+0000] {taskinstance.py:2076} INFO - Dependencies all met for dep_context=non-requeueable deps ti=<TaskInstance: ETL.extract_data manual__2025-01-16T04:40:52.988903+00:00 [queued]>
[2025-01-16T04:40:56.260+0000] {taskinstance.py:2076} INFO - Dependencies all met for dep_context=requeueable deps ti=<TaskInstance: ETL.extract_data manual__2025-01-16T04:40:52.988903+00:00 [queued]>
[2025-01-16T04:40:56.261+0000] {taskinstance.py:2306} INFO - Starting attempt 1 of 1
[2025-01-16T04:40:56.275+0000] {taskinstance.py:2330} INFO - Executing <Task(PythonOperator): extract_data> on 2025-01-16 04:40:52.988903+00:00
[2025-01-16T04:40:56.281+0000] {standard_task_runner.py:63} INFO - Started process 4624 to run task
[2025-01-16T04:40:56.286+0000] {standard_task_runner.py:90} INFO - Running: ['airflow', 'tasks', 'run', 'ETL', 'extract_data', 'manual__2025-01-16T04:40:52.988903+00:00', '--job-id', '7', '--raw', '--subdir', 'DAGS_FOLDER/ETL.py', '--cfg-path', '/tmp/tmpujmpor4u']
[2025-01-16T04:40:56.289+0000] {standard_task_runner.py:91} INFO - Job 7: Subtask extract_data
[2025-01-16T04:40:56.357+0000] {task_command.py:426} INFO - Running <TaskInstance: ETL.extract_data manual__2025-01-16T04:40:52.988903+00:00 [running]> on host airflow-scheduler
[2025-01-16T04:40:56.471+0000] {taskinstance.py:2648} INFO - Exporting env vars: AIRFLOW_CTX_DAG_OWNER='Ajied(WhatsApp), Ajied(Email)' AIRFLOW_CTX_DAG_ID='ETL' AIRFLOW_CTX_TASK_ID='extract_data' AIRFLOW_CTX_EXECUTION_DATE='2025-01-16T04:40:52.988903+00:00' AIRFLOW_CTX_TRY_NUMBER='1' AIRFLOW_CTX_DAG_RUN_ID='manual__2025-01-16T04:40:52.988903+00:00'
[2025-01-16T04:40:56.473+0000] {taskinstance.py:430} INFO - ::endgroup::
[2025-01-16T04:40:56.475+0000] {logging_mixin.py:188} INFO - Extracting data from PostgreSQL...
[2025-01-16T04:40:56.475+0000] {taskinstance.py:441} INFO - ::group::Post task execution logs
[2025-01-16T04:40:56.476+0000] {taskinstance.py:2905} ERROR - Task failed with exception
Traceback (most recent call last):
  File "/home/airflow/.local/lib/python3.10/site-packages/airflow/models/taskinstance.py", line 465, in _execute_task
    result = _execute_callable(context=context, **execute_callable_kwargs)
  File "/home/airflow/.local/lib/python3.10/site-packages/airflow/models/taskinstance.py", line 432, in _execute_callable
    return execute_callable(context=context, **execute_callable_kwargs)
  File "/home/airflow/.local/lib/python3.10/site-packages/airflow/models/baseoperator.py", line 401, in wrapper
    return func(self, *args, **kwargs)
  File "/home/airflow/.local/lib/python3.10/site-packages/airflow/operators/python.py", line 235, in execute
    return_value = self.execute_callable()
  File "/home/airflow/.local/lib/python3.10/site-packages/airflow/operators/python.py", line 252, in execute_callable
    return self.python_callable(*self.op_args, **self.op_kwargs)
  File "/opt/airflow/dags/ETL.py", line 10, in extract
    return extract_data()
  File "/opt/airflow/dags/resources/extract.py", line 51, in extract_data
    products_df = pl.read_database(sql=products, connection_uri=connection_url)
TypeError: read_database() got an unexpected keyword argument 'sql'
[2025-01-16T04:40:56.503+0000] {taskinstance.py:1206} INFO - Marking task as FAILED. dag_id=ETL, task_id=extract_data, run_id=manual__2025-01-16T04:40:52.988903+00:00, execution_date=20250116T044052, start_date=20250116T044056, end_date=20250116T044056
[2025-01-16T04:40:56.519+0000] {standard_task_runner.py:110} ERROR - Failed to execute job 7 for task extract_data (read_database() got an unexpected keyword argument 'sql'; 4624)
[2025-01-16T04:40:56.540+0000] {local_task_job_runner.py:240} INFO - Task exited with return code 1
[2025-01-16T04:40:56.568+0000] {taskinstance.py:3503} INFO - 0 downstream tasks scheduled from follow-on schedule check
[2025-01-16T04:40:56.574+0000] {local_task_job_runner.py:222} INFO - ::endgroup::
